[2025-05-15T10:29:01.763+0000] {taskinstance.py:1087} INFO - Dependencies all met for <TaskInstance: sales_ingestion.load_csv_to_postgres manual__2025-05-15T10:29:00.729749+00:00 [queued]>
[2025-05-15T10:29:01.769+0000] {taskinstance.py:1087} INFO - Dependencies all met for <TaskInstance: sales_ingestion.load_csv_to_postgres manual__2025-05-15T10:29:00.729749+00:00 [queued]>
[2025-05-15T10:29:01.770+0000] {taskinstance.py:1283} INFO - 
--------------------------------------------------------------------------------
[2025-05-15T10:29:01.770+0000] {taskinstance.py:1284} INFO - Starting attempt 1 of 1
[2025-05-15T10:29:01.770+0000] {taskinstance.py:1285} INFO - 
--------------------------------------------------------------------------------
[2025-05-15T10:29:01.780+0000] {taskinstance.py:1304} INFO - Executing <Task(PythonOperator): load_csv_to_postgres> on 2025-05-15 10:29:00.729749+00:00
[2025-05-15T10:29:01.783+0000] {standard_task_runner.py:55} INFO - Started process 473 to run task
[2025-05-15T10:29:01.785+0000] {standard_task_runner.py:82} INFO - Running: ['***', 'tasks', 'run', 'sales_ingestion', 'load_csv_to_postgres', 'manual__2025-05-15T10:29:00.729749+00:00', '--job-id', '29', '--raw', '--subdir', 'DAGS_FOLDER/upload_csv_to_postgres.py', '--cfg-path', '/tmp/tmp_4f4bt0f']
[2025-05-15T10:29:01.786+0000] {standard_task_runner.py:83} INFO - Job 29: Subtask load_csv_to_postgres
[2025-05-15T10:29:01.828+0000] {task_command.py:389} INFO - Running <TaskInstance: sales_ingestion.load_csv_to_postgres manual__2025-05-15T10:29:00.729749+00:00 [running]> on host 92d0d3de5da6
[2025-05-15T10:29:01.971+0000] {taskinstance.py:1513} INFO - Exporting the following env vars:
AIRFLOW_CTX_DAG_OWNER=***
AIRFLOW_CTX_DAG_ID=sales_ingestion
AIRFLOW_CTX_TASK_ID=load_csv_to_postgres
AIRFLOW_CTX_EXECUTION_DATE=2025-05-15T10:29:00.729749+00:00
AIRFLOW_CTX_TRY_NUMBER=1
AIRFLOW_CTX_DAG_RUN_ID=manual__2025-05-15T10:29:00.729749+00:00
[2025-05-15T10:29:01.974+0000] {taskinstance.py:1772} ERROR - Task failed with exception
Traceback (most recent call last):
  File "/home/airflow/.local/lib/python3.7/site-packages/airflow/operators/python.py", line 175, in execute
    return_value = self.execute_callable()
  File "/home/airflow/.local/lib/python3.7/site-packages/airflow/operators/python.py", line 192, in execute_callable
    return self.python_callable(*self.op_args, **self.op_kwargs)
  File "/opt/airflow/dags/upload_csv_to_postgres.py", line 24, in load_csv_with_pandas
    df = pd.read_csv(csv_path, sep=',')
  File "/home/airflow/.local/lib/python3.7/site-packages/pandas/util/_decorators.py", line 311, in wrapper
    return func(*args, **kwargs)
  File "/home/airflow/.local/lib/python3.7/site-packages/pandas/io/parsers/readers.py", line 586, in read_csv
    return _read(filepath_or_buffer, kwds)
  File "/home/airflow/.local/lib/python3.7/site-packages/pandas/io/parsers/readers.py", line 482, in _read
    parser = TextFileReader(filepath_or_buffer, **kwds)
  File "/home/airflow/.local/lib/python3.7/site-packages/pandas/io/parsers/readers.py", line 811, in __init__
    self._engine = self._make_engine(self.engine)
  File "/home/airflow/.local/lib/python3.7/site-packages/pandas/io/parsers/readers.py", line 1040, in _make_engine
    return mapping[engine](self.f, **self.options)  # type: ignore[call-arg]
  File "/home/airflow/.local/lib/python3.7/site-packages/pandas/io/parsers/c_parser_wrapper.py", line 51, in __init__
    self._open_handles(src, kwds)
  File "/home/airflow/.local/lib/python3.7/site-packages/pandas/io/parsers/base_parser.py", line 229, in _open_handles
    errors=kwds.get("encoding_errors", "strict"),
  File "/home/airflow/.local/lib/python3.7/site-packages/pandas/io/common.py", line 707, in get_handle
    newline="",
FileNotFoundError: [Errno 2] No such file or directory: '/data/sales.csv'
[2025-05-15T10:29:01.982+0000] {taskinstance.py:1327} INFO - Marking task as FAILED. dag_id=sales_ingestion, task_id=load_csv_to_postgres, execution_date=20250515T102900, start_date=20250515T102901, end_date=20250515T102901
[2025-05-15T10:29:01.990+0000] {standard_task_runner.py:105} ERROR - Failed to execute job 29 for task load_csv_to_postgres ([Errno 2] No such file or directory: '/data/sales.csv'; 473)
[2025-05-15T10:29:01.997+0000] {local_task_job.py:159} INFO - Task exited with return code 1
[2025-05-15T10:29:02.011+0000] {taskinstance.py:2582} INFO - 0 downstream tasks scheduled from follow-on schedule check
